Workbook

Sheet Outlet_Master
A1: Outlet ID | B1: Outlet Name | C1: KA Manager | D1: Employee ID | E1: Agent / Distributor | F1: Region / City | G1: Channel / Segment | H1: Active Status | I1: Fridge Installed | J1: Latitude | K1: Longitude | L1: Notes
A2: 102444 | B2: Hill Bottom | C2: Alemayehu | D2: 3359 | E2: Guade Lakew Wondifraw | F2: Addis Ababa | H2: Yes | I2: No
A3: 1001215 | B3: Pasfic Hotel | C3: Alemayehu | D3: 3359 | E3: Guade Lakew Wondifraw | F3: Addis Ababa | H3: Yes | I3: No
A4: 1001463 | B4: Grand Mark Addis | C4: Alemayehu | D4: 3359 | E4: Fibath Trading | F4: Addis Ababa | H4: Yes | I4: Yes
A5: 1001971 | B5: Yod Abyssinya Hotel | C5: Alemayehu | D5: 3359 | E5: Guade Lakew Wondifraw | F5: Addis Ababa | H5: Yes | I5: No
A6: 1001973 | B6: Archi Hotel | C6: Alemayehu | D6: 3359 | E6: Guade Lakew Wondifraw | F6: Addis Ababa | H6: Yes | I6: No
A7: 1002921 | B7: Ararat Hotel | C7: Alemayehu | D7: 3359 | E7: Guade Lakew Wondifraw | F7: Addis Ababa | H7: Yes | I7: Yes
A8: 1048012 | B8: Top Ten Hotel | C8: Alemayehu | D8: 3359 | E8: Guade Lakew Wondifraw | F8: Addis Ababa | H8: Yes | I8: No
A9: 1050773 | B9: Meklit liyu kurt | C9: Alemayehu | D9: 3359 | E9: Guade Lakew Wondifraw | F9: Addis Ababa | H9: Yes | I9: Yes
A10: 1055371 | B10: Bellevue Hotel | C10: Alemayehu | D10: 3359 | E10: Guade Lakew Wondifraw | F10: Addis Ababa | H10: Yes | I10: No
A11: 1057633 | B11: Mera bar & restaurant | C11: Alemayehu | D11: 3359 | E11: Guade Lakew Wondifraw | F11: Addis Ababa | H11: Yes | I11: Yes
A12: 1066138 | B12: Kebede leyu kurt | C12: Alemayehu | D12: 3359 | E12: Guade Lakew Wondifraw | F12: Addis Ababa | H12: Yes | I12: No
A13: 1090447 | B13: Agape liyukurt | C13: Alemayehu | D13: 3359 | E13: Guade Lakew Wondifraw | F13: Addis Ababa | H13: Yes | I13: Yes
... A376: 11304338 | B376: ZigZag Hotel and spa | C376: Netsanet | D376: 251 | E376: Dawileon Trading Plc | F376: Addis Ababa | H376: Yes | I376: No
A377: 1000089 | B377: Messob Habesha Bucher | C377: Vaccant | D377: Vaccant | E377: DA Beverage | F377: Addis Ababa | H377: Yes | I377: Yes
A378: 1002751 | B378: Dagim Tinsae Bar and Restaurant | C378: Vaccant | D378: Vaccant | E378: DA Beverage | F378: Addis Ababa | H378: Yes | I378: No
A379: 1002764 | B379: Country House | C379: Vaccant | D379: Vaccant | E379: DA Beverage | F379: Addis Ababa | H379: Yes | I379: Yes
A380: 1002822 | B380: Debube Grocery | C380: Vaccant | D380: Vaccant | E380: DA Beverage | F380: Addis Ababa | H380: Yes | I380: Yes
A381: 1005031 | B381: Wedmamachoch Butchery | C381: Vaccant | D381: Vaccant | E381: da Beverage | F381: Addis Ababa | H381: Yes | I381: No
A382: 1005033 | B382: yerga Butchery | C382: Vaccant | D382: Vaccant | E382: DA Beverage | F382: Addis Ababa | H382: Yes | I382: No
A383: 1006224 | B383: Soramba Hotel | C383: Vaccant | D383: Vaccant | E383: DA Beverage | F383: Addis Ababa | H383: Yes | I383: Yes
A384: 1019609 | B384: Axum Hotel | C384: Vaccant | D384: Vaccant | E384: DA Beverage | F384: Addis Ababa | H384: Yes | I384: No
A385: 1019703 | B385: Tobia Teji Bet | C385: Vaccant | D385: Vaccant | E385: DA Beverage | F385: Addis Ababa | H385: Yes | I385: No
A386: 1020487 | B386: yetemche Traditional house | C386: Vaccant | D386: Vaccant | E386: DA Beverage | F386: Addis Ababa | H386: Yes | I386: No
A387: 1022948 | B387: Afro politan Hotel | C387: Vaccant | D387: Vaccant | E387: DA Beverage | F387: Addis Ababa | H387: Yes | I387: No
A388: 1024024 | B388: Sunrise Hotel | C388: Vaccant | D388: Vaccant | E388: DA Beverage | F388: Addis Ababa | H388: Yes | I388: Yes
... A413: 2928190 | B413: Debebe Bar and Restaurant | C413: Vaccant | D413: Vaccant | E413: DA Beverage | F413: Addis Ababa | H413: Yes | I413: Yes
A414: 1563992 | B414: Le Jardin Bar and Restaurant | C414: Alemayehu | D414: 3359 | F414: Addis Ababa | H414: Yes | I414: No
A415: 1048118 | B415: Africana Bar and restaurant | C415: Alemayehu | D415: 3359 | F415: Addis Ababa | H415: Yes | I415: No
A416: 2221331 | B416: Keebede Butchery | C416: Alemayehu | D416: 3359 | F416: Addis Ababa | H416: Yes | I416: No
A417: 2789801 | B417: Chuchina Resturant | C417: Alemayehu | D417: 3359 | F417: Addis Ababa | H417: Yes | I417: No
A418: 1000032 | B418: Tagese Butchery | C418: Alemayehu | D418: 3359 | F418: Addis Ababa | H418: Yes | I418: No
A419: 1211600 | B419: Yonas Chercher | C419: Alemayehu | D419: 3359 | F419: Addis Ababa | H419: Yes | I419: Yes
A420: 2956808 | B420: Avocado luxury spa | C420: Netsanet | D420: 251 | F420: Addis Ababa | H420: Yes | I420: No

Sheet Visit_Plan
A1: Outlet Name | B1: ID | C1: area | D1: Date | E1: KA Manager | F1: Leave | G1: Employee ID | H1: Column1
A2: Zegeye kurt bet | B2: 2837203 | C2: Summit | D2: 46174 | E2: Alemayehu | F2: No | G2: 3359 | H2: =_xlfn.XLOOKUP(B2,Outlet_Master!A:A,Outlet_Master!A:A) -> 2837203
A3: Fekire kunespagna | B3: 2254017 | C3: Summit | D3: 46174 | E3: Alemayehu | F3: No | G3: 3359 | H3: =_xlfn.XLOOKUP(B3,Outlet_Master!A:A,Outlet_Master!A:A) -> 2254017
A4: Genesis Fishe | C4: Summit | D4: 46174 | E4: Alemayehu | F4: No | G4: 3359 | H4: =_xlfn.XLOOKUP(B4,Outlet_Master!A:A,Outlet_Master!A:A) -> 0
A5: Hop Lounge | B5: 2123024 | C5: Summit | D5: 46174 | E5: Alemayehu | F5: No | G5: 3359 | H5: =_xlfn.XLOOKUP(B5,Outlet_Master!A:A,Outlet_Master!A:A) -> 2123024
A6: Yonas chercher buchery no3 | B6: 2196866 | C6: Summit | D6: 46174 | E6: Alemayehu | F6: No | G6: 3359 | H6: =_xlfn.XLOOKUP(B6,Outlet_Master!A:A,Outlet_Master!A:A) -> 2196866
A7: Flex Adddis | C7: Summit | D7: 46174 | E7: Alemayehu | F7: No | G7: 3359 | H7: =_xlfn.XLOOKUP(B7,Outlet_Master!A:A,Outlet_Master!A:A) -> 0
A8: Cheru medihaniyalem liyu kurt | B8: 1567781 | C8: Summit | D8: 46174 | E8: Alemayehu | F8: No | G8: 3359 | H8: =_xlfn.XLOOKUP(B8,Outlet_Master!A:A,Outlet_Master!A:A) -> 1567781
A9: wecare special kurt | B9: 2003128 | C9: Summit | D9: 46174 | E9: Alemayehu | F9: No | G9: 3359 | H9: =_xlfn.XLOOKUP(B9,Outlet_Master!A:A,Outlet_Master!A:A) -> 2003128
A10: bricks lounge | B10: 1579550 | C10: Summit | D10: 46174 | E10: Alemayehu | F10: No | G10: 3359 | H10: =_xlfn.XLOOKUP(B10,Outlet_Master!A:A,Outlet_Master!A:A) -> 1579550
A11: L-classice | B11: 2938660 | C11: Summit | D11: 46174 | E11: Alemayehu | F11: No | G11: 3359 | H11: =_xlfn.XLOOKUP(B11,Outlet_Master!A:A,Outlet_Master!A:A) -> 2938660
A12: lexury winner fiyel bet | B12: 2608618 | C12: Summit | D12: 46174 | E12: Alemayehu | F12: No | G12: 3359 | H12: =_xlfn.XLOOKUP(B12,Outlet_Master!A:A,Outlet_Master!A:A) -> 2608618
A13: Chuchu supermarket and restaurant | B13: 2933482 | C13: Summit | D13: 46174 | E13: Alemayehu | F13: No | G13: 3359 | H13: =_xlfn.XLOOKUP(B13,Outlet_Master!A:A,Outlet_Master!A:A) -> 2933482
A14: Noble plate | C14: Summit | D14: 46174 | E14: Alemayehu | F14: No | G14: 3359 | H14: =_xlfn.XLOOKUP(B14,Outlet_Master!A:A,Outlet_Master!A:A) -> 0
A15: Hundaf bar no3 | B15: 2495983 | C15: Summit | D15: 46175 | E15: Alemayehu | F15: No | G15: 3359 | H15: =_xlfn.XLOOKUP(B15,Outlet_Master!A:A,Outlet_Master!A:A) -> 2495983
A16: Yebate Kitfo | C16: Summit | D16: 46175 | E16: Alemayehu | F16: No | G16: 3359 | H16: =_xlfn.XLOOKUP(B16,Outlet_Master!A:A,Outlet_Master!A:A) -> 0
A17: variety Supermarket | C17: Summit | D17: 46175 | E17: Alemayehu | F17: No | G17: 3359 | H17: =_xlfn.XLOOKUP(B17,Outlet_Master!A:A,Outlet_Master!A:A) -> 0
A18: 70 Dereja | B18: 2931271 | C18: Summit | D18: 46175 | E18: Alemayehu | F18: No | G18: 3359 | H18: =_xlfn.XLOOKUP(B18,Outlet_Master!A:A,Outlet_Master!A:A) -> 2931271
A19: 70 Dereja | B19: 1213545 | C19: Summit | D19: 46175 | E19: Alemayehu | F19: No | G19: 3359 | H19: =_xlfn.XLOOKUP(B19,Outlet_Master!A:A,Outlet_Master!A:A) -> 1213545
A20: 12 Menota lounge | B20: 2780028 | C20: Summit | D20: 46175 | E20: Alemayehu | F20: No | G20: 3359 | H20: =_xlfn.XLOOKUP(B20,Outlet_Master!A:A,Outlet_Master!A:A) -> 2780028
A21: Lucy Lounge | C21: Summit | D21: 46175 | E21: Alemayehu | F21: No | G21: 3359 | H21: =_xlfn.XLOOKUP(B21,Outlet_Master!A:A,Outlet_Master!A:A) -> #N/A
A22: Senayt Lounge | C22: Summit | D22: 46175 | E22: Alemayehu | F22: No | G22: 3359 | H22: =_xlfn.XLOOKUP(B22,Outlet_Master!A:A,Outlet_Master!A:A) -> 0
A23: She Semaneya | B23: 2845807 | C23: Summit | D23: 46175 | E23: Alemayehu | F23: No | G23: 3359 | H23: =_xlfn.XLOOKUP(B23,Outlet_Master!A:A,Outlet_Master!A:A) -> 2845807
A24: Geche Asa Bete | B24: 2910023 | C24: Summit | D24: 46175 | E24: Alemayehu | F24: No | G24: 3359 | H24: =_xlfn.XLOOKUP(B24,Outlet_Master!A:A,Outlet_Master!A:A) -> 2910023
A25: Tadese Asa Bete | B25: 2675988 | C25: Summit | D25: 46175 | E25: Alemayehu | F25: No | G25: 3359 | H25: =_xlfn.XLOOKUP(B25,Outlet_Master!A:A,Outlet_Master!A:A) -> 2675988
A26: Bamies Bistro | B26: 2275518 | C26: Summit | D26: 46175 | E26: Alemayehu | F26: No | G26: 3359 | H26: =_xlfn.XLOOKUP(B26,Outlet_Master!A:A,Outlet_Master!A:A) -> 2275518
A27: Hanot Bar and Restautrant | B27: 2773109 | C27: Summit | D27: 46175 | E27: Alemayehu | F27: No | G27: 3359 | H27: =_xlfn.XLOOKUP(B27,Outlet_Master!A:A,Outlet_Master!A:A) -> 2773109
A28: Mekelite Kurt | B28: 2789793 | C28: 22 | D28: 46176 | E28: Alemayehu | F28: No | G28: 3359 | H28: =_xlfn.XLOOKUP(B28,Outlet_Master!A:A,Outlet_Master!A:A) -> 2789793
A29: Kot Hotel | B29: 16827727 | C29: 24 | D29: 46176 | E29: Alemayehu | F29: No | G29: 3359 | H29: =_xlfn.XLOOKUP(B29,Outlet_Master!A:A,Outlet_Master!A:A) -> 16827727
A30: Ende Bate bar | C30: 24 | D30: 46176 | E30: Alemayehu | F30: No | G30: 3359 | H30: =_xlfn.XLOOKUP(B30,Outlet_Master!A:A,Outlet_Master!A:A) -> 0
A31: Yared Kurt | B31: 2722948 | C31: 24 | D31: 46176 | E31: Alemayehu | F31: No | G31: 3359 | H31: =_xlfn.XLOOKUP(B31,Outlet_Master!A:A,Outlet_Master!A:A) -> 2722948
A32: L and Z China Hotel | B32: 1063353 | C32: 24 | D32: 46176 | E32: Alemayehu | F32: No | G32: 3359 | H32: =_xlfn.XLOOKUP(B32,Outlet_Master!A:A,Outlet_Master!A:A) -> 1063353
A33: Seven Hotel | B33: 1571808 | C33: Mebrat hile | D33: 46176 | E33: Alemayehu | F33: No | G33: 3359 | H33: =_xlfn.XLOOKUP(B33,Outlet_Master!A:A,Outlet_Master!A:A) -> 1571808
A34: Daily Mart | C34: Mebrat hile | D34: 46176 | E34: Alemayehu | F34: No | G34: 3359 | H34: =_xlfn.XLOOKUP(B34,Outlet_Master!A:A,Outlet_Master!A:A) -> 0
A35: Rebka butchery | B35: 1214332 | C35: Mebrat hile | D35: 46176 | E35: Alemayehu | F35: No | G35: 3359 | H35: =_xlfn.XLOOKUP(B35,Outlet_Master!A:A,Outlet_Master!A:A) -> 1214332
A36: Mereb Butchery | B36: 2336521 | C36: Mebrat hile | D36: 46176 | E36: Alemayehu | F36: No | G36: 3359 | H36: =_xlfn.XLOOKUP(B36,Outlet_Master!A:A,Outlet_Master!A:A) -> 2336521
A37: Central butchery | B37: 2808896 | C37: Mebrat hile | D37: 46176 | E37: Alemayehu | F37: No | G37: 3359 | H37: =_xlfn.XLOOKUP(B37,Outlet_Master!A:A,Outlet_Master!A:A) -> 2808896
A38: Habesha butchery | B38: 2848593 | C38: Mebrat hile | D38: 46176 | E38: Alemayehu | F38: No | G38: 3359 | H38: =_xlfn.XLOOKUP(B38,Outlet_Master!A:A,Outlet_Master!A:A) -> 2848593
A39: Green Bar and restaurant | B39: 1091718 | C39: Summit Safari | D39: 46177 | E39: Alemayehu | F39: No | G39: 3359 | H39: =_xlfn.XLOOKUP(B39,Outlet_Master!A:A,Outlet_Master!A:A) -> 1091718
A40: On Time | B40: 1216866 | C40: Summit Safari | D40: 46177 | E40: Alemayehu | F40: No | G40: 3359 | H40: =_xlfn.XLOOKUP(B40,Outlet_Master!A:A,Outlet_Master!A:A) -> 1216866
...

Sheet Sales_Target
A1: Outlet ID | B1: KA Manager | C1: Employee ID | D1: Previous 3 mon Avg | E1: 3 month AVG | F1: Similar Month PY | G1: Ambition | H1: Target
A2: 2350521 | B2: Netsanet | C2: 251 | D2: 890 | E2: =D2/3 -> 296.66667 | F2: 193 | G2: 0.1 | H2: 269.31667
A3: 2180441 | B3: Netsanet | C3: 251 | D3: 947 | E3: =D3/3 -> 315.66667 | F3: 173 | G3: 0.1 | H3: 268.76667
A4: 1225952 | B4: Netsanet | C4: 251 | D4: 457 | E4: =D4/3 -> 152.33333 | F4: 320 | G4: 0.1 | H4: 259.78333
A5: 2400336 | B5: Netsanet | C5: 251 | D5: 397 | E5: =D5/3 -> 132.33333 | F5: 306 | G5: 0.1 | H5: 241.08333
A6: 1000403 | B6: Netsanet | C6: 251 | D6: 312 | E6: =D6/3 -> 104 | F6: 283 | G6: 0.1 | H6: 212.85
A7: 1090267 | B7: Netsanet | C7: 251 | D7: 443 | E7: =D7/3 -> 147.66667 | F7: 183 | G7: 0.1 | H7: 181.86667
A8: 1651657 | B8: Netsanet | C8: 251 | D8: 755 | E8: =D8/3 -> 251.66667 | F8: 52 | G8: 0.1 | H8: 167.01667
A9: 1001746 | B9: Netsanet | C9: 251 | D9: 144 | E9: =D9/3 -> 48 | F9: 238 | G9: 0.1 | H9: 157.3
A10: 1057503 | B10: Netsanet | C10: 251 | D10: 379 | E10: =D10/3 -> 126.33333 | F10: 158 | G10: 0.1 | H10: 156.38333
A11: 1133405 | B11: Netsanet | C11: 251 | D11: 231 | E11: =D11/3 -> 77 | F11: 166 | G11: 0.1 | H11: 133.65
A12: 1233883 | B12: Netsanet | C12: 251 | D12: 351 | E12: =D12/3 -> 117 | F12: 113 | G12: 0.1 | H12: 126.5
A13: 1125087 | B13: Netsanet | C13: 251 | D13: 437 | E13: =D13/3 -> 145.66667 | F13: 81 | G13: 0.1 | H13: 124.66667
... A377: 2387988 | B377: Alemayehu | C377: 3359 | D377: 93 | E377: =D377/3 -> 31 | F377: 25 | G377: 0.1 | H377: 33
A378: 1563992 | B378: Alemayehu | C378: 3359 | D378: 56 | E378: =D378/3 -> 18.666667 | F378: =_xlfn.XLOOKUP(A378,[1]Sheet1!$D:$D,[1]Sheet1!$E:$E) -> 13 | G378: 0.1 | H378: 33
A379: 1048118 | B379: Alemayehu | C379: 3359 | D379: 37 | E379: =D379/3 -> 12.333333 | F379: =_xlfn.XLOOKUP(A379,[1]Sheet1!$D:$D,[1]Sheet1!$E:$E) -> 15 | G379: 0.1 | H379: 33
A380: 2221331 | B380: Alemayehu | C380: 3359 | D380: 19 | E380: =D380/3 -> 6.3333333 | F380: =_xlfn.XLOOKUP(A380,[1]Sheet1!$D:$D,[1]Sheet1!$E:$E) -> 8 | G380: 0.1 | H380: 33
A381: 2789801 | B381: Alemayehu | C381: 3359 | D381: 22 | E381: =D381/3 -> 7.3333333 | F381: =_xlfn.XLOOKUP(A381,[1]Sheet1!$D:$D,[1]Sheet1!$E:$E) -> 11 | G381: 0.1 | H381: 33
A382: 1000032 | B382: Alemayehu | C382: 3359 | D382: 59 | E382: =D382/3 -> 19.666667 | F382: =_xlfn.XLOOKUP(A382,[1]Sheet1!$D:$D,[1]Sheet1!$E:$E) -> 12 | G382: 0.1 | H382: 33
A383: 1211600 | B383: Alemayehu | C383: 3359 | D383: 40 | E383: =D383/3 -> 13.333333 | F383: =_xlfn.XLOOKUP(A383,[1]Sheet1!$D:$D,[1]Sheet1!$E:$E) -> 16 | G383: 0.1 | H383: 33
A384: 1570898 | B384: Vaccant | C384: Vaccant | D384: 299 | E384: =D384/3 -> 99.666667 | F384: 129 | G384: 0.1 | H384: 125.76667
A385: 2008591 | B385: Vaccant | C385: Vaccant | D385: 288 | E385: =D385/3 -> 96 | F385: 111 | G385: 0.1 | H385: 113.85
A386: 1633255 | B386: Vaccant | C386: Vaccant | D386: 313 | E386: =D386/3 -> 104.33333 | F386: 59 | G386: 0.1 | H386: 89.833333
A387: 1000089 | B387: Vaccant | C387: Vaccant | D387: 175 | E387: =D387/3 -> 58.333333 | F387: 85 | G387: 0.1 | H387: 78.833333
A388: 2030063 | B388: Vaccant | C388: Vaccant | D388: 206 | E388: =D388/3 -> 68.666667 | F388: 71 | G388: 0.1 | H388: 76.816667
A389: 2928190 | B389: Vaccant | C389: Vaccant | D389: 237 | E389: =D389/3 -> 79 | F389: 0 | G389: 0.1 | H389: 43.45
A390: 1005033 | B390: Vaccant | C390: Vaccant | D390: 223 | E390: =D390/3 -> 74.333333 | F390: 0 | G390: 0.1 | H390: 40.883333
A391: 1212855 | B391: Vaccant | C391: Vaccant | D391: 149 | E391: =D391/3 -> 49.666667 | F391: 23 | G391: 0.1 | H391: 39.966667
A392: 1685640 | B392: Vaccant | C392: Vaccant | D392: 96 | E392: =D392/3 -> 32 | F392: 35 | G392: 0.1 | H392: 36.85
A393: 1026682 | B393: Vaccant | C393: Vaccant | D393: 0 | E393: =D393/3 -> 0 | F393: 0 | G393: 0.1 | H393: 33
A394: 1216338 | B394: Vaccant | C394: Vaccant | D394: 0 | E394: =D394/3 -> 0 | F394: 0 | G394: 0.1 | H394: 33
A395: 2273600 | B395: Vaccant | C395: Vaccant | D395: 0 | E395: =D395/3 -> 0 | F395: 0 | G395: 0.1 | H395: 33
... A420: 2882207 | B420: Vaccant | C420: Vaccant | D420: 155 | E420: =D420/3 -> 51.666667 | F420: 0 | G420: 0.1 | H420: 33

Sheet Visit_Actual
A1: Employee Responsible For Account | B1: Account | C1: End Date in Local Time Zone | D1: 1 Visits Account
A2: 3359 | B2: 2275518 | C2: 46175 | D2: 1
A3: 3359 | B3: 2495983 | C3: 46175 | D3: 1
A4: 3359 | B4: 2675988 | C4: 46175 | D4: 1
A5: 3359 | B5: 2773109 | C5: 46175 | D5: 1
A6: 3359 | B6: 2845807 | C6: 46175 | D6: 1
A7: 3359 | B7: 2910023 | C7: 46175 | D7: 1
A8: 3359 | B8: 2931271 | C8: 46175 | D8: 1
A9: 3359 | B9: 2933406 | C9: 46175 | D9: 1
A10: 3359 | B10: 2951769 | C10: 46175 | D10: 1
A11: 3359 | B11: 2953966 | C11: 46175 | D11: 1
A12: 215 | B12: 1000358 | C12: 46176 | D12: 1
A13: 215 | B13: 1000359 | C13: 46176 | D13: 1
... A41: 215 | B41: 2957288 | C41: 46176 | D41: 1

Sheet Actual Sales
A1: Calendar Day | B1: Account ID (Account) | C1: Sales Unit | D1: Product | E1: Requested Quantity
A2: 46174 | B2: 1006658 | C2: Seblu Deresse Mekonnen | D2: Habesha Beer | E2: 10
A3: 46174 | B3: 1020914 | C3: Seblu Deresse Mekonnen | D3: Habesha Beer | E3: 6
A4: 46174 | B4: 1005003 | C4: Seblu Deresse Mekonnen | D4: Habesha Beer | E4: 5
A5: 46174 | B5: 1025077 | C5: Seblu Deresse Mekonnen | D5: Habesha Beer | E5: 7
A6: 46174 | B6: 1566608 | C6: Seblu Deresse Mekonnen | D6: Negus Malt | E6: 7
A7: 46174 | B7: 1005021 | C7: Seblu Deresse Mekonnen | D7: Habesha Beer | E7: 10
A8: 46174 | B8: 1020915 | C8: Seblu Deresse Mekonnen | D8: Habesha Beer | E8: 5
A9: 46174 | B9: 1020915 | C9: Seblu Deresse Mekonnen | D9: Negus Malt | E9: 7
A10: 46174 | B10: 1005009 | C10: Seblu Deresse Mekonnen | D10: Habesha Beer | E10: 6
A11: 46174 | B11: 1005009 | C11: Seblu Deresse Mekonnen | D11: Negus Malt | E11: 5
A12: 46174 | B12: 1133987 | C12: Seblu Deresse Mekonnen | D12: Habesha Beer | E12: 5
A13: 46174 | B13: 2904276 | C13: Seblu Deresse Mekonnen | D13: Habesha Beer | E13: 6
... A3852: 46176 | B3852: 1567380 | C3852: Shimeles Solomon Ahmed | D3852: Negus Malt | E3852: 2

Sheet KPI_Config
A1: KPI | B1: Weight % | C1: Included in Final KPI | D1: Included in Provisional KPI | F1: Reporting Name | G1: Execution Standard % | H1: Comment
A2: Volume | B2: 0.5 | C2: Yes | D2: Yes | F2: Netsanet
A3: JP Adherence | B3: 0.25 | C3: Yes | D3: Yes | F3: Alemayehu
A4: Execution Standard | B4: 0.25 | C4: Yes | D4: No | F4: Chandra
A5: Visit Completion | B5: 0 | C5: No | D5: No | F5: Vaccant
A6: Cold Coverage | B6: 0 | C6: No | D6: No
