Workbook

Sheet Sheet1
A1: no | B1: Agent | C1: Outlet Name | D1: ID | E1: GDF Availability | F1: DBE Availability | G1: Remark
A2: 41 | B2: Fibath Trading | C2: Lucy Lounge | E2: NO | F2: NO
A3: 93 | B3: Fibath Trading | C3: Social bar(selo house | D3: 2060901 | E3: NO | F3: NO
A4: 95 | B4: Fibath Trading | C4: Tarik Lounge | D4: 2757908 | E4: Available | F4: NO
A5: 107 | B5: Shimeles | C5: Fikire kunspagna | D5: 2905492 | E5: Available | F5: NO
A6: 135 | B6: shimeles | C6: Beyene leda | D6: 2267797 | E6: NO | F6: Available
A7: 137 | B7: shimeles | C7: Z Blue one Lounge | D7: 1579113 | E7: NO | F7: NO
A8: 138 | B8: shimeles | C8: Cheru Adama Special Kurt | D8: 2926342 | E8: NO | F8: NO
A9: 69 | B9: Fibath Trading | C9: Kot Hotel | D9: 16827727 | E9: NO | F9: NO
A10: 49 | B10: Fibath Trading | C10: Worka Buna | D10: 2953966 | E10: NO | F10: NO
A11: 25 | B11: Fibath Trading | C11: L-classice | D11: 2938660 | E11: NO | F11: NO
A12: 28 | B12: Fibath Trading | C12: Chuchu supermarket and restaurant | D12: 2933482 | E12: NO | F12: NO
A13: 37 | B13: Fibath Trading | C13: 70 Dereja | D13: 2931271 | E13: NO | F13: NO
A14: 44 | B14: Fibath Trading | C14: Geche Asa Bete | D14: 2910023 | E14: NO | F14: NO
... A59: 116 | B59: Fibath Trading | C59: The Chill Spot | D59: 1214830 | E59: NO | F59: NO
A60: 80 | B60: Fibath Trading | C60: Goro addis butchery | D60: 1214424 | E60: Available
A61: 76 | B61: Fibath Trading | C61: Rebka butchery | D61: 1214332 | E61: Available | F61: Available
A62: 38 | B62: Fibath Trading | C62: 70 Dereja | D62: 1213545 | E62: NO | F62: NO
A63: 106 | B63: Shimeles | C63: Yod jame hotel | D63: 1210611 | E63: Available | F63: NO
A64: 110 | B64: Shimeles | C64: Damo butchery (bulbula | D64: 1207997 | E64: NO | F64: NO
A65: 102 | B65: Fibath Trading | C65: Mandela bar | D65: 1193110 | E65: Available | F65: Available
A66: 87 | B66: Fibath Trading | C66: Dusk Addis | D66: 1126810 | E66: NO | F66: NO
A67: 104 | B67: Shimeles | C67: Ethiolink bar no2 | D67: 1125112 | E67: NO | F67: NO
A68: 85 | B68: shimeles | C68: Yohannes Kurt | D68: 1091921 | E68: Available | F68: Available
A69: 51 | B69: Fibath Trading | C69: Green Bar and restaurant | D69: 1091718 | E69: NO | F69: NO
A70: 14 | B70: Fibath Trading | C70: The Hub Addis Ababa | D70: 1090850 | E70: NO | F70: No
A71: 72 | B71: Fibath Trading | C71: L and Z China Hotel | D71: 1063353 | E71: NO | F71: NO
A72: 124 | B72: Fibath Trading | C72: Foyat Hotel | D72: 1058189 | E72: NO | F72: NO
... A91: 126 | B91: Fibath Trading | C91: Yomana Kitefo Bet | D91: 1005311 | E91: Available | F91: NO
A92: 91 | B92: Fibath Trading | D92: NO | F92: NO
A93: 5 | B93: Fibath Trading | C93: Nexus Hotel | D93: 1003655 | E93: Available | F93: No
A94: 83 | B94: Fibath Trading | C94: Zekir buchery | D94: 1003056 | E94: Available
A95: 105 | B95: Shimeles | C95: Bridge Hotel | D95: 1002031 | E95: Available | F95: Available
A96: 123 | B96: Fibath Trading | C96: Airport Motel | D96: 1001697 | E96: Available | F96: NO
A97: 98 | B97: Fibath Trading | C97: Yoalu bar and resturant | D97: 1001664 | E97: Available | F97: NO
A98: 100 | B98: Fibath Trading | C98: Kertina butchery(gerji t | D98: 1001652 | E98: Available | F98: No
A99: 11 | B99: Fibath Trading | C99: Beemnet Bar and Restaurant | D99: 1001640 | E99: Available | F99: No
A100: 82 | B100: Fibath Trading | C100: goro Abiza no1 | D100: 1001466 | E100: Available | F100: Available
A101: 56 | B101: Fibath Trading | C101: Grand Mark Addis | D101: 1001463 | E101: Available | F101: NO
A102: 81 | B102: Fibath Trading | C102: Goro Abiza no2 | D102: 1001463 | E102: Available | F102: Available
...

Sheet Sheet2
A1: Outlet ID | B1: Outlet Name | C1: KA Manager | D1: Employee ID | E1: Agent / Distributor | F1: Region / City | G1: Channel / Segment | H1: Active Status | I1: Fridge Installed | J1: Latitude | K1: Longitude | L1: Notes
A2: 2608618 | B2: lexury winner fiyel bet | C2: Alemayehu | D2: 3359 | E2: Fibath Trading | F2: Addis Ababa | H2: Yes | I2: Yes | M2: =_xlfn.XLOOKUP(A2,Sheet1!D:D,Sheet1!D:D) -> #N/A
A3: 2387988 | B3: Sheger Kurt | C3: Alemayehu | D3: 3359 | E3: Shimeles Solomon Ahmed | F3: Addis Ababa | H3: Yes | I3: Yes | M3: =_xlfn.XLOOKUP(A3,Sheet1!D:D,Sheet1!D:D) -> #N/A
A4: 2780028 | B4: 12 Menota lounge | C4: Alemayehu | D4: 3359 | E4: Fibath Trading | F4: Addis Ababa | H4: Yes | I4: No | M4: =_xlfn.XLOOKUP(A4,Sheet1!D:D,Sheet1!D:D) -> #N/A
A5: 1775066 | B5: 2RN Selemon Hotel&Spa | C5: Alemayehu | D5: 3359 | E5: Guade Lakew Wondifraw | F5: Addis Ababa | H5: Yes | I5: No | M5: =_xlfn.XLOOKUP(A5,Sheet1!D:D,Sheet1!D:D) -> #N/A
A6: 2931271 | B6: 70 Dereja | C6: Alemayehu | D6: 3359 | E6: Fibath Trading | F6: Addis Ababa | H6: Yes | I6: No | M6: =_xlfn.XLOOKUP(A6,Sheet1!D:D,Sheet1!D:D) -> #N/A
A7: 1213545 | B7: 70 Dereja | C7: Alemayehu | D7: 3359 | E7: Fibath Trading | F7: Addis Ababa | H7: Yes | I7: No | M7: =_xlfn.XLOOKUP(A7,Sheet1!D:D,Sheet1!D:D) -> #N/A
A8: 1013652 | B8: Addisiniya Hotel | C8: Alemayehu | D8: 3359 | E8: Fibath Trading | F8: Addis Ababa | H8: Yes | I8: Yes | M8: =_xlfn.XLOOKUP(A8,Sheet1!D:D,Sheet1!D:D) -> #N/A
A9: 1743376 | B9: Adu Tg Furnished Apartment | C9: Alemayehu | D9: 3359 | E9: Guade Lakew Wondifraw | F9: Addis Ababa | H9: Yes | I9: No | M9: =_xlfn.XLOOKUP(A9,Sheet1!D:D,Sheet1!D:D) -> #N/A
A10: 1048118 | B10: Africana Bar and restaurant | C10: Alemayehu | D10: 3359 | F10: Addis Ababa | H10: Yes | I10: No | M10: =_xlfn.XLOOKUP(A10,Sheet1!D:D,Sheet1!D:D) -> #N/A
A11: 1090447 | B11: Agape liyukurt | C11: Alemayehu | D11: 3359 | E11: Guade Lakew Wondifraw | F11: Addis Ababa | H11: Yes | I11: Yes | M11: =_xlfn.XLOOKUP(A11,Sheet1!D:D,Sheet1!D:D) -> #N/A
A12: 1001697 | B12: Airport Motel | C12: Alemayehu | D12: 3359 | E12: Fibath Trading | F12: Addis Ababa | H12: Yes | I12: Yes | M12: =_xlfn.XLOOKUP(A12,Sheet1!D:D,Sheet1!D:D) -> #N/A
A13: 2092084 | B13: Akukulu Supermarket | C13: Alemayehu | D13: 3359 | E13: Guade Lakew Wondifraw | F13: Addis Ababa | H13: Yes | I13: Yes | M13: =_xlfn.XLOOKUP(A13,Sheet1!D:D,Sheet1!D:D) -> #N/A
A14: 1215666 | B14: Amene butchery | C14: Alemayehu | D14: 3359 | E14: Shimeles Solomon Ahmed | F14: Addis Ababa | H14: Yes | I14: Yes | M14: =_xlfn.XLOOKUP(A14,Sheet1!D:D,Sheet1!D:D) -> #N/A
A15: 2876726 | B15: Andinet kurti & kitfo no2 | C15: Alemayehu | D15: 3359 | E15: Guade Lakew Wondifraw | F15: Addis Ababa | H15: Yes | I15: Yes | M15: =_xlfn.XLOOKUP(A15,Sheet1!D:D,Sheet1!D:D) -> #N/A
A16: 1002921 | B16: Ararat Hotel | C16: Alemayehu | D16: 3359 | E16: Guade Lakew Wondifraw | F16: Addis Ababa | H16: Yes | I16: Yes | M16: =_xlfn.XLOOKUP(A16,Sheet1!D:D,Sheet1!D:D) -> #N/A
A17: 1001973 | B17: Archi Hotel | C17: Alemayehu | D17: 3359 | E17: Guade Lakew Wondifraw | F17: Addis Ababa | H17: Yes | I17: No | M17: =_xlfn.XLOOKUP(A17,Sheet1!D:D,Sheet1!D:D) -> #N/A
A18: 1237298 | B18: Aselefeche Mergia Hotel | C18: Alemayehu | D18: 3359 | E18: Guade Lakew Wondifraw | F18: Addis Ababa | H18: Yes | I18: No | M18: =_xlfn.XLOOKUP(A18,Sheet1!D:D,Sheet1!D:D) -> #N/A
A19: 1008615 | B19: Atlas International Hotel | C19: Alemayehu | D19: 3359 | E19: Fibath Trading | F19: Addis Ababa | H19: Yes | I19: No | M19: =_xlfn.XLOOKUP(A19,Sheet1!D:D,Sheet1!D:D) -> #N/A
A20: 2275518 | B20: Bamies Bistro | C20: Alemayehu | D20: 3359 | E20: Fibath Trading | F20: Addis Ababa | H20: Yes | I20: No | M20: =_xlfn.XLOOKUP(A20,Sheet1!D:D,Sheet1!D:D) -> #N/A
A21: 1001640 | B21: Beemnet Bar and Restaurant | C21: Alemayehu | D21: 3359 | E21: Fibath Trading | F21: Addis Ababa | H21: Yes | I21: Yes | M21: =_xlfn.XLOOKUP(A21,Sheet1!D:D,Sheet1!D:D) -> #N/A
A22: 1593192 | B22: Bekiber special kurt ena lounge | C22: Alemayehu | D22: 3359 | E22: Guade Lakew Wondifraw | F22: Addis Ababa | H22: Yes | I22: Yes | M22: =_xlfn.XLOOKUP(A22,Sheet1!D:D,Sheet1!D:D) -> #N/A
... A38: 1561673 | B38: Chillies Addis Hotel & Restaurant | C38: Alemayehu | D38: 3359 | E38: Fibath Trading | F38: Addis Ababa | H38: Yes | I38: No | M38: =_xlfn.XLOOKUP(A38,Sheet1!D:D,Sheet1!D:D) -> #N/A
A39: 2789801 | B39: Chuchina Resturant | C39: Alemayehu | D39: 3359 | F39: Addis Ababa | H39: Yes | I39: No | M39: =_xlfn.XLOOKUP(A39,Sheet1!D:D,Sheet1!D:D) -> #N/A
A40: 2933482 | B40: Chuchu supermarket and restaurant | C40: Alemayehu | D40: 3359 | E40: Fibath Trading | F40: Addis Ababa | H40: Yes | I40: No | M40: =_xlfn.XLOOKUP(A40,Sheet1!D:D,Sheet1!D:D) -> #N/A
A41: 2888215 | B41: Dames leyu kurt | C41: Alemayehu | D41: 3359 | E41: Guade Lakew Wondifraw | F41: Addis Ababa | H41: Yes | I41: No | M41: =_xlfn.XLOOKUP(A41,Sheet1!D:D,Sheet1!D:D) -> #N/A
A42: 1207997 | B42: Damo butchery (bulbula | C42: Alemayehu | D42: 3359 | E42: Shimeles Solomon Ahmed | F42: Addis Ababa | H42: Yes | I42: Yes | M42: =_xlfn.XLOOKUP(A42,Sheet1!D:D,Sheet1!D:D) -> #N/A
A43: 1014751 | B43: Dawit Brundo | C43: Alemayehu | D43: 3359 | E43: Fibath Trading | F43: Addis Ababa | H43: Yes | I43: Yes | M43: =_xlfn.XLOOKUP(A43,Sheet1!D:D,Sheet1!D:D) -> #N/A
A44: 2879434 | B44: Doubel Tree by hilton | C44: Alemayehu | D44: 3359 | E44: Fibath Trading | F44: Addis Ababa | H44: Yes | I44: No | M44: =_xlfn.XLOOKUP(A44,Sheet1!D:D,Sheet1!D:D) -> #N/A
A45: 1126810 | B45: Dusk Addis | C45: Alemayehu | D45: 3359 | E45: Fibath Trading | F45: Addis Ababa | H45: Yes | I45: No | M45: =_xlfn.XLOOKUP(A45,Sheet1!D:D,Sheet1!D:D) -> #N/A
A46: 1125112 | B46: Ethiolink bar no2 | C46: Alemayehu | D46: 3359 | E46: Shimeles Solomon Ahmed | F46: Addis Ababa | H46: Yes | I46: Yes | M46: =_xlfn.XLOOKUP(A46,Sheet1!D:D,Sheet1!D:D) -> #N/A
A47: 2417722 | B47: Fantu Supermarket | C47: Alemayehu | D47: 3359 | E47: Fibath Trading | F47: Addis Ababa | H47: Yes | I47: No | M47: =_xlfn.XLOOKUP(A47,Sheet1!D:D,Sheet1!D:D) -> #N/A
A48: 1010501 | B48: Feke Kunspagna | C48: Alemayehu | D48: 3359 | E48: Fibath Trading | F48: Addis Ababa | H48: Yes | I48: Yes | M48: =_xlfn.XLOOKUP(A48,Sheet1!D:D,Sheet1!D:D) -> #N/A
A49: 2254017 | B49: Fekire kunespagna | C49: Alemayehu | D49: 3359 | E49: Fibath Trading | F49: Addis Ababa | H49: Yes | I49: Yes | M49: =_xlfn.XLOOKUP(A49,Sheet1!D:D,Sheet1!D:D) -> #N/A
A50: 290592 | B50: Fikire kunspagna | C50: Alemayehu | D50: 3359 | E50: Shimeles Solomon Ahmed | F50: Addis Ababa | H50: Yes | I50: No | M50: =_xlfn.XLOOKUP(A50,Sheet1!D:D,Sheet1!D:D) -> #N/A
A51: 1013578 | B51: Fkire kunspagna no 2 | C51: Alemayehu | D51: 3359 | E51: Shimeles Solomon Ahmed | F51: Addis Ababa | H51: Yes | I51: Yes | M51: =_xlfn.XLOOKUP(A51,Sheet1!D:D,Sheet1!D:D) -> #N/A
... A71: 1066138 | B71: Kebede leyu kurt | C71: Alemayehu | D71: 3359 | E71: Guade Lakew Wondifraw | F71: Addis Ababa | H71: Yes | I71: No | M71: =_xlfn.XLOOKUP(A71,Sheet1!D:D,Sheet1!D:D) -> #N/A
A72: 2221331 | B72: Keebede Butchery | C72: Alemayehu | D72: 3359 | F72: Addis Ababa | H72: Yes | I72: No | M72: =_xlfn.XLOOKUP(A72,Sheet1!D:D,Sheet1!D:D) -> #N/A
A73: 1564382 | B73: Kena Hotel | C73: Alemayehu | D73: 3359 | E73: Fibath Trading | F73: Addis Ababa | H73: Yes | I73: No | M73: =_xlfn.XLOOKUP(A73,Sheet1!D:D,Sheet1!D:D) -> #N/A
A74: 1001652 | B74: Kertina butchery(gerji t | C74: Alemayehu | D74: 3359 | E74: Fibath Trading | F74: Addis Ababa | H74: Yes | I74: Yes | M74: =_xlfn.XLOOKUP(A74,Sheet1!D:D,Sheet1!D:D) -> #N/A
...
