Workbook

Sheet Sheet
A1: Outlet | B1: Id | C1: Area
A2: Agape liyukurt | B2: 1090447 | C2: Addis Ababa Ayat condominium
A3: Lemore Bar And Restaurant | B3: 1233135 | C3: Addis Ababa Ayat condominium
A4: Andinet kurti & kitfo no2 | B4: 2876726 | C4: Addis Ababa Ayat condominium
A5: Setke addis liyukurt | B5: 2935114 | C5: Addis Ababa Ayat 2
A6: Sitota Kurti And Kitfo | B6: 2675040 | C6: Addis Ababa Ayat 2
A7: nor Addis Kurt | B7: 1580270 | C7: chefie condominium
A8: Nor shger leyu kurtina | B8: 8078175 | C8: Ayat 1
A9: kebab Kurt ena kitfo | B9: 2417439 | C9: Ayat 1
A10: Haletaw Ha Kurt ena Kitfo | B10: 1613091 | C10: Ayat 1
A11: Zequals kitfo bet | B11: 1225868 | C11: Ayat condominium
A12: Kana bar | B12: 1127393 | C12: Ayat condominium
A13: Dames leyu kurt | B13: 2888215 | C13: Ayat condominium
... A88: enderase bar&restaurant | B88: 1000495 | C88: Ayate

Sheet Sheet1
A1: Outlet ID | B1: Outlet Name | C1: KA Manager | D1: Employee ID | E1: Agent | F1: Region / City | G1: Area | H1: Segment | I1: Status | J1: Fridge Installed | K1: Draught Installed | L1: Latitude | M1: Longitude | N1: Remark
A2: 2273600 | B2: Alem Sefa Butchery | C2: London | D2: 2526 | E2: DA Beverage | F2: Addis Ababa | G2: Addis Ababa kazanchis | I2: Active | J2: No | K2: No
A3: 1569222 | B3: Karavan Coffee | C3: London | D3: 2526 | E3: DA Beverage | F3: Addis Ababa | G3: Addis Ababa Megenagna 2 | I3: Active | J3: No | K3: No
A4: 2365391 | B4: Harer bar and restaurant | C4: London | D4: 2526 | E4: DA Beverage | F4: Addis Ababa | G4: Megenagna | I4: Active | J4: Yes | K4: No
A5: 1775066 | B5: 2RN Selemon Hotel&Spa | C5: London | D5: 2526 | E5: Guade Lakew Wondifraw | F5: Addis Ababa | G5: Sendafa | I5: Active | J5: No | K5: No
A6: 1743376 | B6: Adu Tg Furnished Apartment | C6: London | D6: 2526 | E6: Guade Lakew Wondifraw | F6: Addis Ababa | G6: Legetafo Stadium | I6: Active | J6: No | K6: No
A7: 1002921 | B7: Ararat Hotel | C7: London | D7: 2526 | E7: Guade Lakew Wondifraw | F7: Addis Ababa | G7: Addis Ababa Yeka Park | I7: Active | J7: No | K7: No
A8: 102444 | B8: Hill Bottom | C8: London | D8: 2526 | E8: Guade Lakew Wondifraw | F8: Addis Ababa | G8: Ayat | I8: Active | J8: No | K8: No
A9: 2922321 | B9: Summit Valley Lounge | C9: London | D9: 2526 | E9: Guade Lakew Wondifraw | F9: Addis Ababa | G9: Summit 30 meter | I9: Active | J9: No | K9: No
A10: 1569322 | B10: Sheger Gebeta | C10: London | D10: 2526 | E10: Guade Lakew Wondifraw | F10: Addis Ababa | G10: Addis Ababa Sunshine Real Estate | I10: Active | J10: No | K10: Yes
A11: 2789123 | B11: Thrice Brother's Bar | C11: London | D11: 2526 | E11: Guade Lakew Wondifraw | F11: Addis Ababa | G11: Sunshine Real Estate | I11: Active | J11: No | K11: Yes
A12: 2092084 | B12: Akukulu Supermarket | C12: London | D12: 2526 | E12: Guade Lakew Wondifraw | F12: Addis Ababa | G12: Addis Ababa Ayat condominium | I12: Active | J12: Yes | K12: No
A13: 1050773 | B13: Meklit liyu kurt | C13: London | D13: 2526 | E13: Guade Lakew Wondifraw | F13: Addis Ababa | G13: Addis Ababa Ayat condominium | I13: Active | J13: Yes | K13: No
A14: 1131448 | B14: Semur Butchery | C14: London | D14: 2526 | E14: Guade Lakew Wondifraw | F14: Addis Ababa | G14: kotebe | I14: Active | J14: Yes | K14: No
A15: 8078175 | B15: Nor shger leyu kurtina | C15: London | D15: 2526 | F15: Addis Ababa | I15: Active | J15: Yes | K15: Yes
A16: 2960501 | B16: the grand place Hotel | C16: London | D16: 2526 | F16: Addis Ababa | I16: Active | J16: No | K16: No
A17: 2957911 | B17: hailu liyu Kurt ena kitfo | C17: London | D17: 2526 | F17: Addis Ababa | I17: Active | J17: No | K17: Yes
A18: 2935114 | B18: Serke addis liyukurt | C18: London | D18: 2526 | E18: Guade Lakew Wondifraw | F18: Addis Ababa | G18: Addis Ababa Ayat 2 | I18: Active | J18: No | K18: No
A19: 2928190 | B19: Debebe Bar and Restaurant | C19: London | D19: 2526 | E19: DA Beverage | F19: Addis Ababa | G19: Addis Ababa Ferensay | I19: Active | J19: Yes | K19: No
A20: 2888215 | B20: Dames leyu kurt | C20: London | D20: 2526 | E20: Guade Lakew Wondifraw | F20: Addis Ababa | G20: Addis Ababa Ayat condominium | I20: Active | J20: No | K20: No
A21: 2882207 | B21: Seye Fenkenk Butcher | C21: London | D21: 2526 | E21: DA Beverage | F21: Addis Ababa | G21: Addis Ababa Shiro Meda 1 | I21: Active | J21: No | K21: Yes
A22: 2876726 | B22: Andinet kurti & kitfo no2 | C22: London | D22: 2526 | E22: Guade Lakew Wondifraw | F22: Addis Ababa | G22: Addis Ababa Ayat condominium | I22: Active | J22: Yes | K22: Yes
A23: 2739931 | B23: Habesha kurt and kitfo | C23: London | D23: 2526 | F23: Addis Ababa | I23: Active | J23: Yes | K23: Yes
A24: 2716057 | B24: hailu butchery | C24: London | D24: 2526 | F24: Addis Ababa | I24: Active | J24: Yes | K24: Yes
A25: 2675040 | B25: Sitota Kurti And Kitfo | C25: London | D25: 2526 | E25: Guade Lakew Wondifraw | F25: Addis Ababa | G25: Addis Ababa Ayat 2 | I25: Active | J25: Yes | K25: Yes
A26: 2674458 | B26: harer bar&restaurant | C26: London | D26: 2526 | F26: Addis Ababa | I26: Active | J26: Yes | K26: Yes
A27: 2568496 | B27: Henom lounge | C27: London | D27: 2526 | E27: DA Beverage | F27: Addis Ababa | G27: Kasanchise | I27: Active | J27: No | K27: No
A28: 2417439 | B28: kebkab Kurt ena kitfo | C28: London | D28: 2526 | F28: Addis Ababa | I28: Active | J28: Yes | K28: Yes
A29: 2030063 | B29: Ermiyas bar | C29: London | D29: 2526 | E29: DA Beverage | F29: Addis Ababa | G29: Addis Abeba zefemshi | I29: Active | J29: Yes | K29: Yes
A30: 2026360 | B30: fikre kunspagna | C30: London | D30: 2526 | E30: DA Beverage | F30: Addis Ababa | G30: megenagna | I30: Active | J30: Yes | K30: No
A31: 2008591 | B31: Wendmamachoch Butchery | C31: London | D31: 2526 | E31: DA Beverage | F31: Addis Ababa | G31: Addis Ababa Shiro Meda 1 | I31: Active | J31: No | K31: Yes
A32: 1894823 | B32: olive&bread Hotel | C32: London | D32: 2526 | F32: Addis Ababa | I32: Active | J32: No | K32: No
A33: 1716706 | B33: Sole Kurt And Kitfo | C33: London | D33: 2526 | E33: Guade Lakew Wondifraw | F33: Addis Ababa | G33: Addis Ababa Kotebe | I33: Active | J33: No | K33: Yes
A34: 1685640 | B34: Noble House | C34: London | D34: 2526 | E34: DA Beverage | F34: Addis Ababa | G34: Addis Ababa Hilton | I34: Active | J34: No | K34: No
A35: 1659603 | B35: Birrader bar | C35: London | D35: 2526 | E35: Guade Lakew Wondifraw | F35: Addis Ababa | G35: Addis Ababa Ayat condominium | I35: Active | J35: Yes | K35: Yes
A36: 1652835 | B36: Wegert liyu kurt | C36: London | D36: 2526 | E36: Guade Lakew Wondifraw | F36: Addis Ababa | G36: Addis Ababa Ayat condominium | I36: Active | J36: No | K36: No
A37: 1652074 | B37: la Mandolin French Restaurant | C37: London | D37: 2526 | E37: DA Beverage | F37: Addis Ababa | G37: Addis Ababa kebena | I37: Active | J37: No | K37: No
A38: 1633255 | B38: ze bridge bar | C38: London | D38: 2526 | E38: DA Beverage | F38: Addis Ababa | G38: Addis Abeba zefemshi | I38: Active | J38: Yes | K38: Yes
A39: 1613091 | B39: Haletaw Ha Kurt ena Kitfo | C39: London | D39: 2526 | E39: Guade Lakew Wondifraw | F39: Addis Ababa | G39: Ayat 1 | I39: Active | J39: No | K39: Yes
A40: 1593192 | B40: Bekiber special kurt ena lounge | C40: London | D40: 2526 | E40: Guade Lakew Wondifraw | F40: Addis Ababa | G40: Addis Ababa Ayat condominium | I40: Active | J40: Yes | K40: Yes
...

Sheet Sheet2
A1: Outlet ID | B1: Outlet Name | C1: KA Manager | D1: Employee ID | E1: Agent | F1: Region / City | G1: Area | H1: Segment | I1: Status | J1: Fridge Installed | K1: Draught Installed | L1: Latitude | M1: Longitude | N1: Remark
A2: 296038 | B2: Table 5 | C2: London | D2: 2526 | F2: Addis Ababa | G2: Addis Ababa Hilton | I2: Active | J2: No | K2: No
A3: 1000089 | B3: Messob Habesha Bucher | C3: London | D3: 2526 | F3: Addis Ababa | G3: Addis Ababa Megenagna 2 | I3: Active | J3: Yes | K3: Yes
A4: 1000495 | B4: enderase bar&restaurant | C4: London | D4: 2526 | F4: Addis Ababa | G4: Ayate | I4: Active
A5: 1001215 | B5: Pasfic Hotel | C5: London | D5: 2526 | F5: Addis Ababa | G5: Addis Ababa Megenagna 1 | I5: Active | J5: No | K5: No
A6: 1001326 | B6: Addis view Hotel | C6: London | D6: 2526 | F6: Addis Ababa | G6: Addis Ababa university | I6: Active | J6: Yes | K6: No
A7: 1001564 | B7: chibo lounge | C7: London | D7: 2526 | F7: Addis Ababa | G7: Addis Ababa university | I7: Active | J7: No | K7: No
A8: 1001971 | B8: Yod Abyssinya Hotel | C8: London | D8: 2526 | F8: Addis Ababa | G8: Addis Ababa Megenagna 1 | I8: Active | J8: No | K8: No
A9: 1001973 | B9: Archi Hotel | C9: London | D9: 2526 | F9: Addis Ababa | G9: Addis Ababa Megenagna 1 | I9: Active | J9: No | K9: No
A10: 1002134 | B10: sebton bar&restaurant | C10: London | D10: 2526 | F10: Addis Ababa | G10: Addisu gebya | I10: Active
A11: 1005028 | B11: st'maryy butcher | C11: London | D11: 2526 | F11: Addis Ababa | G11: Addisu gebya | I11: Active
A12: 1005033 | B12: yerga Butchery | C12: London | D12: 2526 | F12: Addis Ababa | G12: Addis Ababa Semien Hotel | I12: Active | J12: Yes | K12: No
A13: 1005034 | B13: mesklu barand restaurant | C13: London | D13: 2526 | F13: Addis Ababa | G13: Addis Ababa Gulele 2 | I13: Active | J13: No | K13: No
A14: 1006224 | B14: Soramba Hotel | C14: London | D14: 2526 | F14: Addis Ababa | G14: Addis Ababa Semien Hotel | I14: Active | J14: Yes | K14: No
A15: 1018616 | B15: foyate bar and restaurant | C15: London | D15: 2526 | F15: Addis Ababa | G15: kotebe | I15: Active | J15: Yes | K15: Yes
A16: 1019609 | B16: Axum Hotel | C16: London | D16: 2526 | F16: Addis Ababa | G16: Addis Ababa Megenagna 2 | I16: Active | J16: No | K16: No
A17: 1019703 | B17: Tobia Teji Bet | C17: London | D17: 2526 | F17: Addis Ababa | G17: Addis Ababa Megenagna 2 | I17: Active | J17: Yes | K17: No
A18: 1019834 | B18: Debredamo Hotel | C18: London | D18: 2526 | F18: Addis Ababa | G18: Megenagna | I18: Active | J18: No | K18: No
A19: 1020487 | B19: yetemche Traditional house | C19: London | D19: 2526 | F19: Addis Ababa | G19: Megenagna | I19: Active | J19: No | K19: No
A20: 1022948 | B20: Afro politan Hotel | C20: London | D20: 2526 | F20: Addis Ababa | G20: Addis Ababa Megenagna 2 | I20: Active | J20: Yes | K20: No
A21: 1024024 | B21: Sunrise Hotel | C21: London | D21: 2526 | F21: Addis Ababa | G21: Addis Ababa Semien Hotel | I21: Active | J21: Yes | K21: No
A22: 1025186 | B22: Radisson Blue Hotel | C22: London | D22: 2526 | F22: Addis Ababa | G22: Addis Ababa Hilton | I22: Active | J22: No | K22: No
A23: 1025203 | B23: Jupiter International Hotel | C23: London | D23: 2526 | F23: Addis Ababa | G23: Addis Ababa Hilton | I23: Active | J23: No | K23: No
... A32: 1055371 | B32: Bellevue Hotel | C32: London | D32: 2526 | F32: Addis Ababa | G32: Addis Ababa Yeka Park | I32: Active | J32: No | K32: No
A33: 1055469 | B33: betenda kitfo bate | C33: London | D33: 2526 | F33: Addis Ababa | G33: zefemshi | I33: Active
A34: 1057633 | B34: Mera bar & restaurant | C34: London | D34: 2526 | F34: Addis Ababa | G34: Ayat condominium | I34: Active | J34: Yes | K34: No
A35: 1066138 | B35: Kebede leyu kurt | C35: London | D35: 2526 | F35: Addis Ababa | G35: Ayat condominium | I35: Active | J35: No | K35: No
A36: 1066344 | B36: meskot bar&restaurant | C36: London | D36: 2526 | F36: Addis Ababa | G36: Addis Ababa National Museum | I36: Active | J36: Yes | K36: No
A37: 1090447 | B37: Agape liyukurt | C37: London | D37: 2526 | F37: Addis Ababa | G37: Addis Ababa Ayat condominium | I37: Active | J37: Yes | K37: Yes
A38: 1127393 | B38: Kana bar | C38: London | D38: 2526 | F38: Addis Ababa | G38: Ayat condominium | I38: Active | J38: Yes | K38: Yes
A39: 1163714 | B39: Noah bar&restaurant | C39: London | D39: 2526 | F39: Addis Ababa | G39: National Museum | I39: Active | J39: Yes | K39: Yes
A40: 1200753 | B40: Naketose kitfo | C40: London | D40: 2526 | F40: Addis Ababa | G40: Ayat condominium | I40: Active | J40: Yes | K40: Yes
A41: 1212855 | B41: Mesl Gebeta | C41: London | D41: 2526 | F41: Addis Ababa | G41: Addis Ababa National Museum | I41: Active | J41: Yes | K41: No
A42: 1214760 | B42: Melala Hotel | C42: London | D42: 2526 | F42: Addis Ababa | G42: Addis Ababa Kotebe | I42: Active | J42: No | K42: Yes
A43: 1216716 | B43: 5kilo bar&restaurant | C43: London | D43: 2526 | F43: Addis Ababa | G43: Addis Ababa National Museum | I43: Active | J43: Yes | K43: Yes
A44: 1217404 | B44: Semen Hotel | C44: London | D44: 2526 | F44: Addis Ababa | G44: Addis Ababa Semien Hotel | I44: Active | J44: Yes | K44: No
A45: 1225868 | B45: Zequals kitfo bet | C45: London | D45: 2526 | F45: Addis Ababa | G45: Ayat condominium | I45: Active | J45: Yes | K45: Yes
A46: 1233135 | B46: Lemore Bar And Restaurant | C46: London | D46: 2526 | F46: Addis Ababa | G46: Addis Ababa Ayat condominium | I46: Active | J46: Yes | K46: Yes
A47: 1235470 | B47: sifen bar and restaurant | C47: London | D47: 2526 | F47: Addis Ababa | G47: megenagna | I47: Active
A48: 1237297 | B48: Berlottue Hotel | C48: London | D48: 2526 | F48: Addis Ababa | G48: Addis Ababa Megenagna 1 | I48: Active | J48: No | K48: No
...

Sheet removed outlets and old list  
A1: Outlet ID | B1: Outlet Name | C1: KA Manager | D1: Employee ID | E1: Agent | F1: Region / City | G1: Area | H1: Segment | I1: Status | J1: Fridge Installed | K1: Draught Installed | L1: Latitude | M1: Longitude | N1: Remark
A2: 2273600 | B2: Alem Sefa Butchery | C2: London | D2: 2526 | E2: DA Beverage | F2: Addis Ababa | G2: Addis Ababa kazanchis | I2: Active | J2: No | K2: No | N2: =_xlfn.XLOOKUP(A2,Sheet2!A:A,Sheet2!A:A) -> #N/A
A3: 1569222 | B3: Karavan Coffee | C3: London | D3: 2526 | E3: DA Beverage | F3: Addis Ababa | G3: Addis Ababa Megenagna 2 | I3: Active | J3: No | K3: No | N3: =_xlfn.XLOOKUP(A3,Sheet2!A:A,Sheet2!A:A) -> #N/A
A4: 2365391 | B4: Harer bar and restaurant | C4: London | D4: 2526 | E4: DA Beverage | F4: Addis Ababa | G4: Megenagna | I4: Active | J4: Yes | K4: No | N4: =_xlfn.XLOOKUP(A4,Sheet2!A:A,Sheet2!A:A) -> #N/A
A5: 1743376 | B5: Adu Tg Furnished Apartment | C5: London | D5: 2526 | E5: Guade Lakew Wondifraw | F5: Addis Ababa | G5: Legetafo Stadium | I5: Active | J5: No | K5: No | N5: =_xlfn.XLOOKUP(A5,Sheet2!A:A,Sheet2!A:A) -> #N/A
A6: 1002921 | B6: Ararat Hotel | C6: London | D6: 2526 | E6: Guade Lakew Wondifraw | F6: Addis Ababa | G6: Addis Ababa Yeka Park | I6: Active | J6: No | K6: No | N6: =_xlfn.XLOOKUP(A6,Sheet2!A:A,Sheet2!A:A) -> #N/A
A7: 102444 | B7: Hill Bottom | C7: London | D7: 2526 | E7: Guade Lakew Wondifraw | F7: Addis Ababa | G7: Ayat | I7: Active | J7: No | K7: No | N7: =_xlfn.XLOOKUP(A7,Sheet2!A:A,Sheet2!A:A) -> #N/A
A8: 2922321 | B8: Summit Valley Lounge | C8: London | D8: 2526 | E8: Guade Lakew Wondifraw | F8: Addis Ababa | G8: Summit 30 meter | I8: Active | J8: No | K8: No | N8: =_xlfn.XLOOKUP(A8,Sheet2!A:A,Sheet2!A:A) -> #N/A
A9: 2789123 | B9: Thrice Brother's Bar | C9: London | D9: 2526 | E9: Guade Lakew Wondifraw | F9: Addis Ababa | G9: Sunshine Real Estate | I9: Active | J9: No | K9: Yes | N9: =_xlfn.XLOOKUP(A9,Sheet2!A:A,Sheet2!A:A) -> #N/A
A10: 2092084 | B10: Akukulu Supermarket | C10: London | D10: 2526 | E10: Guade Lakew Wondifraw | F10: Addis Ababa | G10: Addis Ababa Ayat condominium | I10: Active | J10: Yes | K10: No | N10: =_xlfn.XLOOKUP(A10,Sheet2!A:A,Sheet2!A:A) -> #N/A
A11: 1050773 | B11: Meklit liyu kurt | C11: London | D11: 2526 | E11: Guade Lakew Wondifraw | F11: Addis Ababa | G11: Addis Ababa Ayat condominium | I11: Active | J11: Yes | K11: No | N11: =_xlfn.XLOOKUP(A11,Sheet2!A:A,Sheet2!A:A) -> #N/A
A12: 1131448 | B12: Semur Butchery | C12: London | D12: 2526 | E12: Guade Lakew Wondifraw | F12: Addis Ababa | G12: kotebe | I12: Active | J12: Yes | K12: No | N12: =_xlfn.XLOOKUP(A12,Sheet2!A:A,Sheet2!A:A) -> #N/A
A13: 2739931 | B13: Habesha kurt and kitfo | C13: London | D13: 2526 | F13: Addis Ababa | I13: Active | J13: Yes | K13: Yes | N13: =_xlfn.XLOOKUP(A13,Sheet2!A:A,Sheet2!A:A) -> #N/A
A14: 1652835 | B14: Wegert liyu kurt | C14: London | D14: 2526 | E14: Guade Lakew Wondifraw | F14: Addis Ababa | G14: Addis Ababa Ayat condominium | I14: Active | J14: No | K14: No | N14: =_xlfn.XLOOKUP(A14,Sheet2!A:A,Sheet2!A:A) -> #N/A
A15: 1025492 | B15: Efoy Pizza | C15: London | D15: 2526 | E15: DA Beverage | F15: Addis Ababa | G15: Addis Ababa Hilton | I15: Active | J15: No | K15: No | N15: =_xlfn.XLOOKUP(A15,Sheet2!A:A,Sheet2!A:A) -> #N/A
A16: 1002113 | B16: gaber bar and restaurant | C16: London | D16: 2526 | E16: DA Beverage | F16: Addis Ababa | G16: addisu gebya | I16: Active | J16: Yes | K16: Yes | N16: =_xlfn.XLOOKUP(A16,Sheet2!A:A,Sheet2!A:A) -> #N/A
A17: 1001998 | B17: fike kurt and kitfo | C17: London | D17: 2526 | F17: Addis Ababa | I17: Active | J17: Yes | K17: Yes | N17: =_xlfn.XLOOKUP(A17,Sheet2!A:A,Sheet2!A:A) -> #N/A
A18: 8078175 | B18: Nor shger leyu kurtina | C18: London | D18: 2526 | F18: Addis Ababa | I18: Active | J18: Yes | K18: Yes | N18: =_xlfn.XLOOKUP(A18,Sheet2!A:A,Sheet2!A:A) -> 8078175
A19: 2960501 | B19: the grand place Hotel | C19: London | D19: 2526 | F19: Addis Ababa | I19: Active | J19: No | K19: No | N19: =_xlfn.XLOOKUP(A19,Sheet2!A:A,Sheet2!A:A) -> 2960501
A20: 2957911 | B20: hailu liyu Kurt ena kitfo | C20: London | D20: 2526 | F20: Addis Ababa | I20: Active | J20: No | K20: Yes | N20: =_xlfn.XLOOKUP(A20,Sheet2!A:A,Sheet2!A:A) -> 2957911
A21: 2935114 | B21: Serke addis liyukurt | C21: London | D21: 2526 | E21: Guade Lakew Wondifraw | F21: Addis Ababa | G21: Addis Ababa Ayat 2 | I21: Active | J21: No | K21: No | N21: =_xlfn.XLOOKUP(A21,Sheet2!A:A,Sheet2!A:A) -> 2935114
A22: 2928190 | B22: Debebe Bar and Restaurant | C22: London | D22: 2526 | E22: DA Beverage | F22: Addis Ababa | G22: Addis Ababa Ferensay | I22: Active | J22: Yes | K22: No | N22: =_xlfn.XLOOKUP(A22,Sheet2!A:A,Sheet2!A:A) -> 2928190
A23: 2888215 | B23: Dames leyu kurt | C23: London | D23: 2526 | E23: Guade Lakew Wondifraw | F23: Addis Ababa | G23: Addis Ababa Ayat condominium | I23: Active | J23: No | K23: No | N23: =_xlfn.XLOOKUP(A23,Sheet2!A:A,Sheet2!A:A) -> 2888215
A24: 2882207 | B24: Seye Fenkenk Butcher | C24: London | D24: 2526 | E24: DA Beverage | F24: Addis Ababa | G24: Addis Ababa Shiro Meda 1 | I24: Active | J24: No | K24: Yes | N24: =_xlfn.XLOOKUP(A24,Sheet2!A:A,Sheet2!A:A) -> 2882207
A25: 2876726 | B25: Andinet kurti & kitfo no2 | C25: London | D25: 2526 | E25: Guade Lakew Wondifraw | F25: Addis Ababa | G25: Addis Ababa Ayat condominium | I25: Active | J25: Yes | K25: Yes | N25: =_xlfn.XLOOKUP(A25,Sheet2!A:A,Sheet2!A:A) -> 2876726
A26: 2716057 | B26: hailu butchery | C26: London | D26: 2526 | F26: Addis Ababa | I26: Active | J26: Yes | K26: Yes | N26: =_xlfn.XLOOKUP(A26,Sheet2!A:A,Sheet2!A:A) -> 2716057
A27: 2675040 | B27: Sitota Kurti And Kitfo | C27: London | D27: 2526 | E27: Guade Lakew Wondifraw | F27: Addis Ababa | G27: Addis Ababa Ayat 2 | I27: Active | J27: Yes | K27: Yes | N27: =_xlfn.XLOOKUP(A27,Sheet2!A:A,Sheet2!A:A) -> 2675040
A28: 2674458 | B28: harer bar&restaurant | C28: London | D28: 2526 | F28: Addis Ababa | I28: Active | J28: Yes | K28: Yes | N28: =_xlfn.XLOOKUP(A28,Sheet2!A:A,Sheet2!A:A) -> 2674458
A29: 2568496 | B29: Henom lounge | C29: London | D29: 2526 | E29: DA Beverage | F29: Addis Ababa | G29: Kasanchise | I29: Active | J29: No | K29: No | N29: =_xlfn.XLOOKUP(A29,Sheet2!A:A,Sheet2!A:A) -> 2568496
A30: 2417439 | B30: kebkab Kurt ena kitfo | C30: London | D30: 2526 | F30: Addis Ababa | I30: Active | J30: Yes | K30: Yes | N30: =_xlfn.XLOOKUP(A30,Sheet2!A:A,Sheet2!A:A) -> 2417439
A31: 2030063 | B31: Ermiyas bar | C31: London | D31: 2526 | E31: DA Beverage | F31: Addis Ababa | G31: Addis Abeba zefemshi | I31: Active | J31: Yes | K31: Yes | N31: =_xlfn.XLOOKUP(A31,Sheet2!A:A,Sheet2!A:A) -> 2030063
A32: 2026360 | B32: fikre kunspagna | C32: London | D32: 2526 | E32: DA Beverage | F32: Addis Ababa | G32: megenagna | I32: Active | J32: Yes | K32: No | N32: =_xlfn.XLOOKUP(A32,Sheet2!A:A,Sheet2!A:A) -> 2026360
A33: 2008591 | B33: Wendmamachoch Butchery | C33: London | D33: 2526 | E33: DA Beverage | F33: Addis Ababa | G33: Addis Ababa Shiro Meda 1 | I33: Active | J33: No | K33: Yes | N33: =_xlfn.XLOOKUP(A33,Sheet2!A:A,Sheet2!A:A) -> 2008591
A34: 1894823 | B34: olive&bread Hotel | C34: London | D34: 2526 | F34: Addis Ababa | I34: Active | J34: No | K34: No | N34: =_xlfn.XLOOKUP(A34,Sheet2!A:A,Sheet2!A:A) -> 1894823
A35: 1775066 | B35: 2RN Selemon Hotel&Spa | C35: London | D35: 2526 | E35: Guade Lakew Wondifraw | F35: Addis Ababa | G35: Sendafa | I35: Active | J35: No | K35: No | N35: =_xlfn.XLOOKUP(A35,Sheet2!A:A,Sheet2!A:A) -> 1775066
A36: 1716706 | B36: Sole Kurt And Kitfo | C36: London | D36: 2526 | E36: Guade Lakew Wondifraw | F36: Addis Ababa | G36: Addis Ababa Kotebe | I36: Active | J36: No | K36: Yes | N36: =_xlfn.XLOOKUP(A36,Sheet2!A:A,Sheet2!A:A) -> 1716706
A37: 1685640 | B37: Noble House | C37: London | D37: 2526 | E37: DA Beverage | F37: Addis Ababa | G37: Addis Ababa Hilton | I37: Active | J37: No | K37: No | N37: =_xlfn.XLOOKUP(A37,Sheet2!A:A,Sheet2!A:A) -> 1685640
A38: 1659603 | B38: Birrader bar | C38: London | D38: 2526 | E38: Guade Lakew Wondifraw | F38: Addis Ababa | G38: Addis Ababa Ayat condominium | I38: Active | J38: Yes | K38: Yes | N38: =_xlfn.XLOOKUP(A38,Sheet2!A:A,Sheet2!A:A) -> 1659603
A39: 1652074 | B39: la Mandolin French Restaurant | C39: London | D39: 2526 | E39: DA Beverage | F39: Addis Ababa | G39: Addis Ababa kebena | I39: Active | J39: No | K39: No | N39: =_xlfn.XLOOKUP(A39,Sheet2!A:A,Sheet2!A:A) -> 1652074
A40: 1633255 | B40: ze bridge bar | C40: London | D40: 2526 | E40: DA Beverage | F40: Addis Ababa | G40: Addis Abeba zefemshi | I40: Active | J40: Yes | K40: Yes | N40: =_xlfn.XLOOKUP(A40,Sheet2!A:A,Sheet2!A:A) -> 1633255
...
